Workbook

Sheet Sheet6
A3: Row Labels | B3: Count of sales | C3: Count of profit
A4: Maharashtra | B4: 1776 | C4: 1776
A5: Karnataka | B5: 1227 | C5: 1227
A6: Chandigarh | B6: 1186 | C6: 1186
A7: Delhi | B7: 1150 | C7: 1150
A8: Kerala | B8: 1079 | C8: 1079
A9: Tamil Nadu | B9: 1069 | C9: 1069
A10: Gujarat | B10: 1063 | C10: 1063
A11: Telangana | B11: 939 | C11: 939
A12: West Bengal | B12: 872 | C12: 872
A13: Rajasthan | B13: 858 | C13: 858
A14: Uttar Pradesh | B14: 767 | C14: 767
A15: Grand Total | B15: 11986 | C15: 11986

Sheet Sheet5
A3: Row Labels | B3: Count of sales
A4: 2025 | B4: 11986
A5: Jan | B5: 1067
A6: Feb | B6: 899
A7: Mar | B7: 1041
A8: Apr | B8: 982
A9: May | B9: 971
A10: Jun | B10: 979
A11: Jul | B11: 1019
A12: Aug | B12: 965
A13: Sep | B13: 1018
A14: Oct | B14: 1027
A15: Nov | B15: 1007
... A17: Grand Total | B17: 11986

Sheet Sheet8
A3: Row Labels | B3: Count of profit | C3: Count of sales
A4: Consumer | B4: 6702 | C4: 6702
A5: Corporate | B5: 3455 | C5: 3455
A6: Small Business | B6: 1829 | C6: 1829
A7: Grand Total | B7: 11986 | C7: 11986

Sheet Sheet9
A3: Row Labels | B3: Count of sales | C3: Count of profit
A4: P063 | B4: 181 | C4: 181
A5: P005 | B5: 173 | C5: 173
A6: P026 | B6: 173 | C6: 173
A7: P052 | B7: 172 | C7: 172
A8: P038 | B8: 171 | C8: 171
A9: P058 | B9: 169 | C9: 169
A10: P044 | B10: 169 | C10: 169
A11: P032 | B11: 167 | C11: 167
A12: P048 | B12: 165 | C12: 165
A13: P075 | B13: 163 | C13: 163
A14: P053 | B14: 163 | C14: 163
A15: Grand Total | B15: 1866 | C15: 1866

Sheet Dashboard
B2: E-Commerce Sales Analytics Dashboard
B3: Sales, Profit, Customer & Product Performance
B6: Total Orders | C6: Units Sold | D6: Total Sales | E6: Total Profit | F6: Profit Margin
B7: =Sheet3!B2 -> 11985 | C7: =Sheet3!B3 -> 24122 | D7: =Sheet3!B4 -> 4.312538e+08 | E7: =Sheet3!B5 -> 5819150.4 | F7: =Sheet3!B6 -> 0.013493563

Sheet insights
A1: Maharashtra was the highest-performing state by sales.
A2: July recorded the highest monthly sales and profit.
A3: November recorded the lowest monthly sales.
A4: Home Appliances generated the highest category sales.
A5: Fragrance Product 034 had a strong profit margin among high-sales products.
A6: Accessories Product 025 had the lowest margin among products with high sales.
A7: 133 customers were identified as repeat customers in the SQL analysis.
A8: Discount-level profit margins remained relatively stable.

Sheet orders
A1: order_id | B1: order_date | C1: customer_id | D1: product_id | E1: quantity | F1: discount | G1: unit_price | H1: sales | I1: base_margin | J1: profit | K1: Category | L1: State | M1: Customer segement
A2: O000001 | B2: 45867 | C2: C0257 | D2: P013 | E2: 2 | F2: 0.2 | G2: 17633 | H2: 28212.800000000003 | I2: 0.19 | J2: 5507.288722782825 | K2: =_xlfn.XLOOKUP(D2,Products!A:A,Products!C:C,"") -> Home Appliances | L2: =_xlfn.XLOOKUP(C2,Customers!A:A,Customers!D:D,"") -> Delhi | M2: =_xlfn.XLOOKUP(C2,Customers!A:A,Customers!E:E,"") -> Consumer
A3: O000002 | B3: 45961 | C3: C0654 | D3: P032 | E3: 1 | F3: 0.1 | G3: 10888 | H3: 9799.2 | I3: 0.19 | J3: 2266.9387 | K3: =_xlfn.XLOOKUP(D3,Products!A:A,Products!C:C,"") -> Home Appliances | L3: =_xlfn.XLOOKUP(C3,Customers!A:A,Customers!D:D,"") -> Maharashtra | M3: =_xlfn.XLOOKUP(C3,Customers!A:A,Customers!E:E,"") -> Corporate
A4: O000003 | B4: 45953 | C4: C1160 | D4: P027 | E4: 4 | F4: 0.05 | G4: 30563 | H4: 116139.4 | I4: 0.19 | J4: 29980.827828686088 | K4: =_xlfn.XLOOKUP(D4,Products!A:A,Products!C:C,"") -> Home Appliances | L4: =_xlfn.XLOOKUP(C4,Customers!A:A,Customers!D:D,"") -> Telangana | M4: =_xlfn.XLOOKUP(C4,Customers!A:A,Customers!E:E,"") -> Consumer
A5: O000004 | B5: 45754 | C5: C0591 | D5: P051 | E5: 1 | F5: 0.15 | G5: 48370 | H5: 41114.5 | I5: 0.16 | J5: 7104.8769886780665 | K5: =_xlfn.XLOOKUP(D5,Products!A:A,Products!C:C,"") -> Technology | L5: =_xlfn.XLOOKUP(C5,Customers!A:A,Customers!D:D,"") -> West Bengal | M5: =_xlfn.XLOOKUP(C5,Customers!A:A,Customers!E:E,"") -> Consumer
A6: O000005 | B6: 45865 | C6: C0444 | D6: P034 | E6: 2 | F6: 0 | G6: 49003 | H6: 98006 | I6: 0.31 | J6: 28358.475966579732 | K6: =_xlfn.XLOOKUP(D6,Products!A:A,Products!C:C,"") -> Beauty & Personal Care | L6: =_xlfn.XLOOKUP(C6,Customers!A:A,Customers!D:D,"") -> Karnataka | M6: =_xlfn.XLOOKUP(C6,Customers!A:A,Customers!E:E,"") -> Consumer
A7: O000006 | B7: 45794 | C7: C0418 | D7: P028 | E7: 3 | F7: 0.2 | G7: 7879 | H7: 18909.600000000002 | I7: 0.16 | J7: 3354.673069834371 | K7: =_xlfn.XLOOKUP(D7,Products!A:A,Products!C:C,"") -> Technology | L7: =_xlfn.XLOOKUP(C7,Customers!A:A,Customers!D:D,"") -> Telangana | M7: =_xlfn.XLOOKUP(C7,Customers!A:A,Customers!E:E,"") -> Corporate
A8: O000007 | B8: 45841 | C8: C0574 | D8: P073 | E8: 5 | F8: 0.1 | G8: 3110 | H8: 13995 | I8: 0.31 | J8: 3936.8258840192743 | K8: =_xlfn.XLOOKUP(D8,Products!A:A,Products!C:C,"") -> Beauty & Personal Care | L8: =_xlfn.XLOOKUP(C8,Customers!A:A,Customers!D:D,"") -> Telangana | M8: =_xlfn.XLOOKUP(C8,Customers!A:A,Customers!E:E,"") -> Consumer
A9: O000008 | B9: 45733 | C9: C0129 | D9: P072 | E9: 2 | F9: 0.1 | G9: 4623 | H9: 8321.4 | I9: 0.28 | J9: 2691.770663486954 | K9: =_xlfn.XLOOKUP(D9,Products!A:A,Products!C:C,"") -> Office Supplies | L9: =_xlfn.XLOOKUP(C9,Customers!A:A,Customers!D:D,"") -> West Bengal | M9: =_xlfn.XLOOKUP(C9,Customers!A:A,Customers!E:E,"") -> Corporate
A10: O000009 | B10: 45944 | C10: C1011 | D10: P030 | E10: 1 | F10: 0.15 | G10: 26232 | H10: 22297.2 | I10: 0.22 | J10: 4357.815378540655 | K10: =_xlfn.XLOOKUP(D10,Products!A:A,Products!C:C,"") -> Furniture | L10: =_xlfn.XLOOKUP(C10,Customers!A:A,Customers!D:D,"") -> Telangana | M10: =_xlfn.XLOOKUP(C10,Customers!A:A,Customers!E:E,"") -> Consumer
A11: O000010 | B11: 45799 | C11: C0341 | D11: P009 | E11: 1 | F11: 0.15 | G11: 11380 | H11: 9673 | I11: 0.28 | J11: 2643.0513431082604 | K11: =_xlfn.XLOOKUP(D11,Products!A:A,Products!C:C,"") -> Office Supplies | L11: =_xlfn.XLOOKUP(C11,Customers!A:A,Customers!D:D,"") -> Delhi | M11: =_xlfn.XLOOKUP(C11,Customers!A:A,Customers!E:E,"") -> Corporate
A12: O000011 | B12: 45894 | C12: C0810 | D12: P013 | E12: 1 | F12: 0.05 | G12: 17633 | H12: 16751.35 | I12: 0.19 | J12: 2691.6291116790394 | K12: =_xlfn.XLOOKUP(D12,Products!A:A,Products!C:C,"") -> Home Appliances | L12: =_xlfn.XLOOKUP(C12,Customers!A:A,Customers!D:D,"") -> Delhi | M12: =_xlfn.XLOOKUP(C12,Customers!A:A,Customers!E:E,"") -> Consumer
A13: O000012 | B13: 45682 | C13: C0992 | D13: P064 | E13: 2 | F13: 0.25 | G13: 9427 | H13: 14140.5 | I13: 0.22 | J13: 3201.0707372621523 | K13: =_xlfn.XLOOKUP(D13,Products!A:A,Products!C:C,"") -> Furniture | L13: =_xlfn.XLOOKUP(C13,Customers!A:A,Customers!D:D,"") -> Tamil Nadu | M13: =_xlfn.XLOOKUP(C13,Customers!A:A,Customers!E:E,"") -> Consumer
A14: O000013 | B14: 45947 | C14: C0100 | D14: P038 | E14: 3 | F14: 0.25 | G14: 9257 | H14: 20828.25 | I14: 0.16 | J14: 3491.0417295438915 | K14: =_xlfn.XLOOKUP(D14,Products!A:A,Products!C:C,"") -> Technology | L14: =_xlfn.XLOOKUP(C14,Customers!A:A,Customers!D:D,"") -> Karnataka | M14: =_xlfn.XLOOKUP(C14,Customers!A:A,Customers!E:E,"") -> Consumer
A15: O000014 | B15: 45724 | C15: C0039 | D15: P022 | E15: 3 | F15: 0.1 | G15: 5299 | H15: 14307.300000000001 | I15: 0.16 | J15: 2661.0520461352435 | K15: =_xlfn.XLOOKUP(D15,Products!A:A,Products!C:C,"") -> Technology | L15: =_xlfn.XLOOKUP(C15,Customers!A:A,Customers!D:D,"") -> Delhi | M15: =_xlfn.XLOOKUP(C15,Customers!A:A,Customers!E:E,"") -> Corporate
A16: O000015 | B16: 45907 | C16: C0263 | D16: P031 | E16: 1 | F16: 0.1 | G16: 41060 | H16: 36954 | I16: 0.28 | J16: 10501.864009486873 | K16: =_xlfn.XLOOKUP(D16,Products!A:A,Products!C:C,"") -> Office Supplies | L16: =_xlfn.XLOOKUP(C16,Customers!A:A,Customers!D:D,"") -> Kerala | M16: =_xlfn.XLOOKUP(C16,Customers!A:A,Customers!E:E,"") -> Corporate
A17: O000016 | B17: 45775 | C17: C0150 | D17: P042 | E17: 2 | F17: 0.1 | G17: 24549 | H17: 44188.200000000004 | I17: 0.19 | J17: 8467.314014490421 | K17: =_xlfn.XLOOKUP(D17,Products!A:A,Products!C:C,"") -> Home Appliances | L17: =_xlfn.XLOOKUP(C17,Customers!A:A,Customers!D:D,"") -> Kerala | M17: =_xlfn.XLOOKUP(C17,Customers!A:A,Customers!E:E,"") -> Consumer
A18: O000017 | B18: 45730 | C18: C0690 | D18: P062 | E18: 4 | F18: 0.1 | G18: 40809 | H18: 146912.4 | I18: 0.19 | J18: 24962.502461561904 | K18: =_xlfn.XLOOKUP(D18,Products!A:A,Products!C:C,"") -> Home Appliances | L18: =_xlfn.XLOOKUP(C18,Customers!A:A,Customers!D:D,"") -> West Bengal | M18: =_xlfn.XLOOKUP(C18,Customers!A:A,Customers!E:E,"") -> Small Business
A19: O000018 | B19: 45939 | C19: C0813 | D19: P064 | E19: 4 | F19: 0.25 | G19: 9427 | H19: 28281 | I19: 0.22 | J19: 5938.383410973606 | K19: =_xlfn.XLOOKUP(D19,Products!A:A,Products!C:C,"") -> Furniture | L19: =_xlfn.XLOOKUP(C19,Customers!A:A,Customers!D:D,"") -> Karnataka | M19: =_xlfn.XLOOKUP(C19,Customers!A:A,Customers!E:E,"") -> Consumer
A20: O000019 | B20: 46017 | C20: C1144 | D20: P074 | E20: 2 | F20: 0.05 | G20: 28518 | H20: 54184.2 | I20: 0.31 | J20: 14155.516355946893 | K20: =_xlfn.XLOOKUP(D20,Products!A:A,Products!C:C,"") -> Beauty & Personal Care | L20: =_xlfn.XLOOKUP(C20,Customers!A:A,Customers!D:D,"") -> Tamil Nadu | M20: =_xlfn.XLOOKUP(C20,Customers!A:A,Customers!E:E,"") -> Corporate
A21: O000020 | B21: 45667 | C21: C0219 | D21: P009 | E21: 2 | F21: 0 | G21: 11380 | H21: 22760 | I21: 0.28 | J21: 7483.022143328183 | K21: =_xlfn.XLOOKUP(D21,Products!A:A,Products!C:C,"") -> Office Supplies | L21: =_xlfn.XLOOKUP(C21,Customers!A:A,Customers!D:D,"") -> Gujarat | M21: =_xlfn.XLOOKUP(C21,Customers!A:A,Customers!E:E,"") -> Consumer
A22: O000021 | B22: 45868 | C22: C0906 | D22: P044 | E22: 2 | F22: 0.2 | G22: 41116 | H22: 65785.6 | I22: 0.19 | J22: 12282.134430992155 | K22: =_xlfn.XLOOKUP(D22,Products!A:A,Products!C:C,"") -> Home Appliances | L22: =_xlfn.XLOOKUP(C22,Customers!A:A,Customers!D:D,"") -> Maharashtra | M22: =_xlfn.XLOOKUP(C22,Customers!A:A,Customers!E:E,"") -> Consumer
A23: O000022 | B23: 45980 | C23: C1147 | D23: P063 | E23: 1 | F23: 0.05 | G23: 11537 | H23: 10960.15 | I23: 0.22 | J23: 3040.612764819357 | K23: =_xlfn.XLOOKUP(D23,Products!A:A,Products!C:C,"") -> Furniture | L23: =_xlfn.XLOOKUP(C23,Customers!A:A,Customers!D:D,"") -> Karnataka | M23: =_xlfn.XLOOKUP(C23,Customers!A:A,Customers!E:E,"") -> Consumer
A24: O000023 | B24: 45809 | C24: C0244 | D24: P040 | E24: 1 | F24: 0.15 | G24: 43459 | H24: 36940.15 | I24: 0.19 | J24: 6862.1494091139675 | K24: =_xlfn.XLOOKUP(D24,Products!A:A,Products!C:C,"") -> Home Appliances | L24: =_xlfn.XLOOKUP(C24,Customers!A:A,Customers!D:D,"") -> Maharashtra | M24: =_xlfn.XLOOKUP(C24,Customers!A:A,Customers!E:E,"") -> Corporate
A25: O000024 | B25: 45662 | C25: C0886 | D25: P041 | E25: 2 | F25: 0.05 | G25: 40096 | H25: 76182.4 | I25: 0.22 | J25: 11688.334150953106 | K25: =_xlfn.XLOOKUP(D25,Products!A:A,Products!C:C,"") -> Furniture | L25: =_xlfn.XLOOKUP(C25,Customers!A:A,Customers!D:D,"") -> Gujarat | M25: =_xlfn.XLOOKUP(C25,Customers!A:A,Customers!E:E,"") -> Consumer
A26: O000025 | B26: 45852 | C26: C0587 | D26: P072 | E26: 1 | F26: 0.25 | G26: 4623 | H26: 3467.25 | I26: 0.28 | J26: 916.1730085386442 | K26: =_xlfn.XLOOKUP(D26,Products!A:A,Products!C:C,"") -> Office Supplies | L26: =_xlfn.XLOOKUP(C26,Customers!A:A,Customers!D:D,"") -> Maharashtra | M26: =_xlfn.XLOOKUP(C26,Customers!A:A,Customers!E:E,"") -> Consumer
A27: O000026 | B27: 45940 | C27: C0518 | D27: P050 | E27: 2 | F27: 0.15 | G27: 22075 | H27: 37527.5 | I27: 0.16 | J27: 6000.976813307517 | K27: =_xlfn.XLOOKUP(D27,Products!A:A,Products!C:C,"") -> Technology | L27: =_xlfn.XLOOKUP(C27,Customers!A:A,Customers!D:D,"") -> Telangana | M27: =_xlfn.XLOOKUP(C27,Customers!A:A,Customers!E:E,"") -> Consumer
A28: O000027 | B28: 45770 | C28: C1045 | D28: P020 | E28: 2 | F28: 0.2 | G28: 10792 | H28: 17267.2 | I28: 0.28 | J28: 4874.310621806567 | K28: =_xlfn.XLOOKUP(D28,Products!A:A,Products!C:C,"") -> Office Supplies | L28: =_xlfn.XLOOKUP(C28,Customers!A:A,Customers!D:D,"") -> Maharashtra | M28: =_xlfn.XLOOKUP(C28,Customers!A:A,Customers!E:E,"") -> Consumer
A29: O000028 | B29: 45928 | C29: C0190 | D29: P070 | E29: 2 | F29: 0.25 | G29: 40034 | H29: 60051 | I29: 0.28 | J29: 18236.846330652035 | K29: =_xlfn.XLOOKUP(D29,Products!A:A,Products!C:C,"") -> Office Supplies | L29: =_xlfn.XLOOKUP(C29,Customers!A:A,Customers!D:D,"") -> Rajasthan | M29: =_xlfn.XLOOKUP(C29,Customers!A:A,Customers!E:E,"") -> Consumer
... A31: O000030 | B31: 45762 | C31: C0615 | D31: P033 | E31: 1 | F31: 0.1 | G31: 13614 | H31: 12252.6 | I31: 0.19 | J31: 2183.476185384776 | K31: =_xlfn.XLOOKUP(D31,Products!A:A,Products!C:C,"") -> Home Appliances | L31: =_xlfn.XLOOKUP(C31,Customers!A:A,Customers!D:D,"") -> Chandigarh | M31: =_xlfn.XLOOKUP(C31,Customers!A:A,Customers!E:E,"") -> Consumer
A32: O000031 | B32: 45838 | C32: C0856 | D32: P063 | E32: 1 | F32: 0.15 | G32: 11537 | H32: 9806.449999999999 | I32: 0.22 | J32: 1843.370973167945 | K32: =_xlfn.XLOOKUP(D32,Products!A:A,Products!C:C,"") -> Furniture | L32: =_xlfn.XLOOKUP(C32,Customers!A:A,Customers!D:D,"") -> Gujarat | M32: =_xlfn.XLOOKUP(C32,Customers!A:A,Customers!E:E,"") -> Consumer
A33: O000032 | B33: 45701 | C33: C0466 | D33: P057 | E33: 1 | F33: 0.15 | G33: 42988 | H33: 36539.799999999996 | I33: 0.19 | J33: 6422.860349918301 | K33: =_xlfn.XLOOKUP(D33,Products!A:A,Products!C:C,"") -> Home Appliances | L33: =_xlfn.XLOOKUP(C33,Customers!A:A,Customers!D:D,"") -> Chandigarh | M33: =_xlfn.XLOOKUP(C33,Customers!A:A,Customers!E:E,"") -> Consumer
A34: O000033 | B34: 45939 | C34: C0099 | D34: P065 | E34: 5 | F34: 0.05 | G34: 7732 | H34: 36727 | I34: 0.22 | J34: 8857.0247 | K34: =_xlfn.XLOOKUP(D34,Products!A:A,Products!C:C,"") -> Furniture | L34: =_xlfn.XLOOKUP(C34,Customers!A:A,Customers!D:D,"") -> Rajasthan | M34: =_xlfn.XLOOKUP(C34,Customers!A:A,Customers!E:E,"") -> Small Business
A35: O000034 | B35: 45832 | C35: C0830 | D35: P052 | E35: 1 | F35: 0.2 | G35: 38016 | H35: 30412.800000000003 | I35: 0.16 | J35: 5779.7836913779165 | K35: =_xlfn.XLOOKUP(D35,Products!A:A,Products!C:C,"") -> Technology | L35: =_xlfn.XLOOKUP(C35,Customers!A:A,Customers!D:D,"") -> Chandigarh | M35: =_xlfn.XLOOKUP(C35,Customers!A:A,Customers!E:E,"") -> Corporate
A36: O000035 | B36: 45819 | C36: C0997 | D36: P006 | E36: 1 | F36: 0.05 | G36: 14233 | H36: 13521.349999999999 | I36: 0.22 | J36: 2655.7960212909898 | K36: =_xlfn.XLOOKUP(D36,Products!A:A,Products!C:C,"") -> Furniture | L36: =_xlfn.XLOOKUP(C36,Customers!A:A,Customers!D:D,"") -> Tamil Nadu | M36: =_xlfn.XLOOKUP(C36,Customers!A:A,Customers!E:E,"") -> Corporate
A37: O000036 | B37: 46008 | C37: C1107 | D37: P007 | E37: 1 | F37: 0.2 | G37: 32777 | H37: 26221.600000000002 | I37: 0.19 | J37: 5906.281039668003 | K37: =_xlfn.XLOOKUP(D37,Products!A:A,Products!C:C,"") -> Home Appliances | L37: =_xlfn.XLOOKUP(C37,Customers!A:A,Customers!D:D,"") -> Maharashtra | M37: =_xlfn.XLOOKUP(C37,Customers!A:A,Customers!E:E,"") -> Corporate
A38: O000037 | B38: 45997 | C38: C0056 | D38: P009 | E38: 2 | F38: 0.1 | G38: 11380 | H38: 20484 | I38: 0.28 | J38: 6143.504797086506 | K38: =_xlfn.XLOOKUP(D38,Products!A:A,Products!C:C,"") -> Office Supplies | L38: =_xlfn.XLOOKUP(C38,Customers!A:A,Customers!D:D,"") -> Kerala | M38: =_xlfn.XLOOKUP(C38,Customers!A:A,Customers!E:E,"") -> Corporate
A39: O000038 | B39: 45797 | C39: C1046 | D39: P061 | E39: 2 | F39: 0.1 | G39: 37834 | H39: 68101.2 | I39: 0.28 | J39: 16953.93354887509 | K39: =_xlfn.XLOOKUP(D39,Products!A:A,Products!C:C,"") -> Office Supplies | L39: =_xlfn.XLOOKUP(C39,Customers!A:A,Customers!D:D,"") -> Tamil Nadu | M39: =_xlfn.XLOOKUP(C39,Customers!A:A,Customers!E:E,"") -> Consumer
A40: O000039 | B40: 45789 | C40: C0580 | D40: P080 | E40: 1 | F40: 0.05 | G40: 657 | H40: 624.15 | I40: 0.22 | J40: 142.70233350567122 | K40: =_xlfn.XLOOKUP(D40,Products!A:A,Products!C:C,"") -> Furniture | L40: =_xlfn.XLOOKUP(C40,Customers!A:A,Customers!D:D,"") -> Tamil Nadu | M40: =_xlfn.XLOOKUP(C40,Customers!A:A,Customers!E:E,"") -> Corporate
A41: O000040 | B41: 45744 | C41: C0185 | D41: P034 | E41: 4 | F41: 0 | G41: 49003 | H41: 196012 | I41: 0.31 | J41: 63300.47735429711 | K41: =_xlfn.XLOOKUP(D41,Products!A:A,Products!C:C,"") -> Beauty & Personal Care | L41: =_xlfn.XLOOKUP(C41,Customers!A:A,Customers!D:D,"") -> Karnataka | M41: =_xlfn.XLOOKUP(C41,Customers!A:A,Customers!E:E,"") -> Consumer
...

Sheet Customers
A1: customer_id | B1: customer_name | C1: city | D1: state | E1: customer_segment
A2: C0001 | B2: Arjun Das | C2: Kolkata | D2: West Bengal | E2: Consumer
A3: C0002 | B3: Isha Sharma | C3: Hyderabad | D3: Telangana | E3: Consumer
A4: C0003 | B4: Rohan Kumar | C4: Lucknow | D4: Uttar Pradesh | E4: Corporate
A5: C0004 | B5: Varun Gupta | C5: Ahmedabad | D5: Gujarat | E5: Corporate
A6: C0005 | B6: Meera Das | C6: Chennai | D6: Tamil Nadu | E6: Consumer
A7: C0006 | B7: Rohan Kumar | C7: Kolkata | D7: West Bengal | E7: Corporate
A8: C0007 | B8: Vikram Iyer | C8: Kochi | D8: Kerala | E8: Consumer
A9: C0008 | B9: Aarav Bhat | C9: Delhi | D9: Delhi | E9: Corporate
A10: C0009 | B10: Arjun Singh | C10: Kolkata | D10: West Bengal | E10: Corporate
A11: C0010 | B11: Meera Nair | C11: Lucknow | D11: Uttar Pradesh | E11: Consumer
A12: C0011 | B12: Aarav Kapoor | C12: Lucknow | D12: Uttar Pradesh | E12: Consumer
... A1201: C1200 | B1201: Kavya Joshi | C1201: Ahmedabad | D1201: Gujarat | E1201: Corporate

Sheet Products
A1: Column1 | B1: Column2 | C1: Column3 | D1: Column4
A2: product_id | B2: product_name | C2: category | D2: sub_category
A3: P001 | B3: Accessories Product 001 | C3: Technology | D3: Accessories
A4: P002 | B4: Small Appliances Product 002 | C4: Home Appliances | D4: Small Appliances
A5: P003 | B5: Accessories Product 003 | C5: Technology | D5: Accessories
A6: P004 | B6: Laptops Product 004 | C6: Technology | D6: Laptops
A7: P005 | B7: Office Furniture Product 005 | C7: Furniture | D7: Office Furniture
A8: P006 | B8: Chairs Product 006 | C8: Furniture | D8: Chairs
A9: P007 | B9: Lighting Product 007 | C9: Home Appliances | D9: Lighting
A10: P008 | B10: Kitchen Product 008 | C10: Home Appliances | D10: Kitchen
A11: P009 | B11: Organizers Product 009 | C11: Office Supplies | D11: Organizers
A12: P010 | B12: Writing Product 010 | C12: Office Supplies | D12: Writing
... A82: P080 | B82: Chairs Product 080 | C82: Furniture | D82: Chairs

Sheet Sheet3
A1: E-commerce Sales Analysis
A2: Total Orders | B2: =COUNTA(_xlfn.UNIQUE(orderstable[order_id])) -> 11985 | E2: Row Labels | F2: Count of sales | G2: Count of profit
A3: Total Units Sold | B3: =SUM(orderstable[quantity]) -> 24122 | E3: Beauty & Personal Care | F3: 867 | G3: 867
A4: Total Sales | B4: =SUM(orderstable[sales]) -> 4.312538e+08 | E4: Furniture | F4: 2116 | G4: 2116
A5: Total Profit | B5: =SUM(orderstable[profit]) -> 5819150.4 | E5: Home Appliances | F5: 4194 | G5: 4194
A6: Profit Margin | B6: =B5/B4 -> 0.013493563 | E6: Office Supplies | F6: 1604 | G6: 1604
E7: Technology | F7: 3205 | G7: 3205
E8: Grand Total | F8: 11986 | G8: 11986
A9: Category | B9: sales | C9: profit
A10: Home Appliances
A11: Technology
A12: Furniture
A13: Office Supplies
A14: Beauty & Personal Care
